Workbook

Sheet 2026
B1: ქვეყანა | C1: 2025 I კვ | D1: 2026 I კვ | E1: ცვლილება 2025/2026 | F1: ცვლილება 2025/2026 %
B2: საერთაშორისო მოგზაურების ვიზიტები | C2: 1314828 | D2: 1300505 | E2: =D2-C2 -> -14323 | F2: =D2/C2-1 -> -0.01089344
B3: სხვა ვიზიტები (არატურისტული) | C3: 142492 | D3: 130143 | E3: =D3-C3 -> -12349 | F3: =D3/C3-1 -> -0.086664514
B4: საერთაშორისო ვიზიტორების მიერ განხორციელებული ვიზიტები | C4: 1172336 | D4: 1170362 | E4: =D4-C4 -> -1974 | F4: =D4/C4-1 -> -0.0016838176
B5: მათ შორის:
B6: ევროპა | C6: 933040 | D6: 946150 | E6: =D6-C6 -> 13110 | F6: =D6/C6-1 -> 0.014050845
B7: ცენტრალური და აღმოსავლეთ ევროპა | C7: 575892 | D7: 572362 | E7: =D7-C7 -> -3530 | F7: =D7/C7-1 -> -0.0061296215
B8: აზერბაიჯანი | C8: 64818 | D8: 59571 | E8: =D8-C8 -> -5247 | F8: =D8/C8-1 -> -0.080949736
B9: ბელარუსი | C9: 17377 | D9: 16904 | E9: =D9-C9 -> -473 | F9: =D9/C9-1 -> -0.027219888
B10: ბულგარეთი | C10: 1837 | D10: 2136 | E10: =D10-C10 -> 299 | F10: =D10/C10-1 -> 0.16276538
B11: ესტონეთი | C11: 1332 | D11: 1138 | E11: =D11-C11 -> -194 | F11: =D11/C11-1 -> -0.14564565
B12: თურქმენეთი | C12: 4263 | D12: 4397 | E12: =D12-C12 -> 134 | F12: =D12/C12-1 -> 0.031433263
B13: ლატვია | C13: 3375 | D13: 2508 | E13: =D13-C13 -> -867 | F13: =D13/C13-1 -> -0.25688889
B14: ლიეტუვა | C14: 3441 | D14: 4470 | E14: =D14-C14 -> 1029 | F14: =D14/C14-1 -> 0.29904098
B15: მოლდოვა | C15: 2717 | D15: 3003 | E15: =D15-C15 -> 286 | F15: =D15/C15-1 -> 0.10526316
B16: პოლონეთი | C16: 10165 | D16: 13651 | E16: =D16-C16 -> 3486 | F16: =D16/C16-1 -> 0.34294147
B17: რუმინეთი | C17: 1473 | D17: 1922 | E17: =D17-C17 -> 449 | F17: =D17/C17-1 -> 0.3048201
... B67: კარიბი | C67: 228 | D67: 304 | E67: =D67-C67 -> 76 | F67: =D67/C67-1 -> 0.33333333
B68: ანგილია | C68: 0 | D68: 0 | E68: =D68-C68 -> 0
B69: ანტიგუა და ბარბუდა | C69: 9 | D69: 12 | E69: =D69-C69 -> 3 | F69: =D69/C69-1 -> 0.33333333
B70: ბარბადოსი | C70: 1 | D70: 3 | E70: =D70-C70 -> 2 | F70: =D70/C70-1 -> 2
B71: ბაჰამის კუნძულები | C71: 4 | D71: 5 | E71: =D71-C71 -> 1 | F71: =D71/C71-1 -> 0.25
B72: გრენადა | C72: 12 | D72: 18 | E72: =D72-C72 -> 6 | F72: =D72/C72-1 -> 0.5
B73: დომინიკა | C73: 81 | D73: 97 | E73: =D73-C73 -> 16 | F73: =D73/C73-1 -> 0.19753086
B74: დომინიკის რესპუბლიკა | C74: 12 | D74: 35 | E74: =D74-C74 -> 23 | F74: =D74/C74-1 -> 1.9166667
B75: ვირჯინიის კუნძულები, ა.შ.შ. | C75: 0 | D75: 0 | E75: =D75-C75 -> 0
B76: ვირჯინიის კუნძულები, დიდი ბრიტანეთი | C76: 0 | D76: 0 | E76: =D76-C76 -> 0
B77: იამაიკა | C77: 9 | D77: 12 | E77: =D77-C77 -> 3 | F77: =D77/C77-1 -> 0.33333333
B78: კაიმანის კუნძულები | C78: 0 | D78: 0 | E78: =D78-C78 -> 0
B79: კუბა | C79: 41 | D79: 42 | E79: =D79-C79 -> 1 | F79: =D79/C79-1 -> 0.024390244
B80: ნიდერლანდის ანტილები | C80: 0 | D80: 0 | E80: =D80-C80 -> 0
B81: პუერტო-რიკო | C81: 0 | D81: 0 | E81: =D81-C81 -> 0
B82: სენტ ვინსენტი და გრენადინები | C82: 0 | D82: 1 | E82: =D82-C82 -> 1
B83: სენტ კრისტოფერი და ნევის | C83: 39 | D83: 62 | E83: =D83-C83 -> 23 | F83: =D83/C83-1 -> 0.58974359
B84: სენტ-ლუსია | C84: 9 | D84: 12 | E84: =D84-C84 -> 3 | F84: =D84/C84-1 -> 0.33333333
B85: ტერქსისა და კაიკოსის კუნძულები | C85: 0 | D85: 0 | E85: =D85-C85 -> 0
B86: ტრინიდადი და ტობაგო | C86: 9 | D86: 2 | E86: =D86-C86 -> -7 | F86: =D86/C86-1 -> -0.77777778
B87: ჰაიტი | C87: 2 | D87: 3 | E87: =D87-C87 -> 1 | F87: =D87/C87-1 -> 0.5
B88: ცენტრალური ამერ. | C88: 97 | D88: 104 | E88: =D88-C88 -> 7 | F88: =D88/C88-1 -> 0.072164948
B89: ბელიზი | C89: 0 | D89: 1 | E89: =D89-C89 -> 1
...

Sheet ტოპ 15
B2: საერთაშორისო ვიზიტორების მიერ განხორციელებული ვიზიტები
C4: ქვეყანა | D4: 2025 I კვ | E4: 2026 I კვ | F4: ცვლილება 2025/2026 | G4: ცვლილება 2025/2026 %
B5: 1 | C5: თურქეთი | D5: 225265 | E5: 238368 | F5: =E5-D5 -> 13103 | G5: =E5/D5-1 -> 0.058167048
B6: 2 | C6: რუსეთი | D6: 219264 | E6: 230717 | F6: =E6-D6 -> 11453 | G6: =E6/D6-1 -> 0.052233837
B7: 3 | C7: სომხეთი | D7: 180805 | E7: 160473 | F7: =E7-D7 -> -20332 | G7: =E7/D7-1 -> -0.11245264
B8: 4 | C8: ისრაელი | D8: 80896 | E8: 66744 | F8: =E8-D8 -> -14152 | G8: =E8/D8-1 -> -0.17494066
B9: 5 | C9: აზერბაიჯანი | D9: 64818 | E9: 59571 | F9: =E9-D9 -> -5247 | G9: =E9/D9-1 -> -0.080949736
B10: 6 | C10: უკრაინა | D10: 24192 | E10: 30119 | F10: =E10-D10 -> 5927 | G10: =E10/D10-1 -> 0.24499835
B11: 7 | C11: ყაზახეთი | D11: 21625 | E11: 21583 | F11: =E11-D11 -> -42 | G11: =E11/D11-1 -> -0.0019421965
B12: 8 | C12: ჩინეთი | D12: 13875 | E12: 20612 | F12: =E12-D12 -> 6737 | G12: =E12/D12-1 -> 0.48554955
B13: 9 | C13: ინდოეთი | D13: 26372 | E13: 18587 | F13: =E13-D13 -> -7785 | G13: =E13/D13-1 -> -0.29519945
B14: 10 | C14: ბელარუსი | D14: 17377 | E14: 16904 | F14: =E14-D14 -> -473 | G14: =E14/D14-1 -> -0.027219888
B15: 11 | C15: გერმანია | D15: 10212 | E15: 14051 | F15: =E15-D15 -> 3839 | G15: =E15/D15-1 -> 0.37593028
B16: 12 | C16: ირანი | D16: 26859 | E16: 13757 | F16: =E16-D16 -> -13102 | G16: =E16/D16-1 -> -0.48780669
... B19: 15 | C19: აშშ | D19: 7558 | E19: 9015 | F19: =E19-D19 -> 1457 | G19: =E19/D19-1 -> 0.19277587
B23: წყარო: საქართველოს შინაგან საქმეთა სამინისტრო, საინფორმაციო-ანალიტიკური დეპარტამენტი

Sheet ვიზიტის ტიპები
B2: საერთაშორისო მოგზაურობის კლასიფიკაცია
B4: ვიზიტის ტიპი | C4: 2025 I კვ | D4: 2026 I კვ | E4: ცვლილება 2025/2026 | F4: ცვლილება 2025/2026 % | G4: წილი%
B5: საერთაშორისო მოგზაურების ვიზიტები | C5: 1314828 | D5: 1300505 | E5: =D5-C5 -> -14323 | F5: =D5/C5-1 -> -0.01089344 | G5: 1
B6: საერთაშორისო ვიზიტორების მიერ განხორციელებული ვიზიტები | C6: 1172336 | D6: 1170362 | E6: =D6-C6 -> -1974 | F6: =D6/C6-1 -> -0.0016838176 | G6: =D6/D5 -> 0.89992887
B7: ტურისტული ვიზიტი | C7: 958947 | D7: 997529 | E7: =D7-C7 -> 38582 | F7: =D7/C7-1 -> 0.040233715 | G7: =D7/D6 -> 0.85232518
B8: ერთდღიანი ვიზიტი | C8: 213389 | D8: 172833 | E8: =D8-C8 -> -40556 | F8: =D8/C8-1 -> -0.19005666 | G8: =D8/D6 -> 0.14767482
B9: სხვა (არატურისტული) | C9: =C5-C6 -> 142492 | D9: =D5-D6 -> 130143 | E9: =D9-C9 -> -12349 | F9: =D9/C9-1 -> -0.086664514 | G9: =D9/D5 -> 0.10007113
B13: წყარო: საქართველოს შინაგან საქმეთა სამინისტრო, საინფორმაციო-ანალიტიკური დეპარტამენტი

Sheet რეგიონები
B2: საერთაშორისო ვიზიტორების მიერ განხორციელებული ვიზიტები
B4: რეგიონი | C4: 2025 I კვ | D4: 2026 I კვ | E4: ცვლილება 2025/2026 | F4: ცვლილება 2025/2026 % | G4: წილი%
B5: მთლიანი ჯამი | C5: ='2026'!C4 -> 1172336 | D5: ='2026'!D4 -> 1170362 | E5: =D5-C5 -> -1974 | F5: =D5/C5-1 -> -0.0016838176 | G5: =D5/D5 -> 1
B6: ევროპა | C6: ='2026'!C6 -> 933040 | D6: ='2026'!D6 -> 946150 | E6: =D6-C6 -> 13110 | F6: =D6/C6-1 -> 0.014050845 | G6: =D6/D5 -> 0.80842509
B7: ამერიკა | C7: ='2026'!C66 -> 10920 | D7: ='2026'!D66 -> 12909 | E7: =D7-C7 -> 1989 | F7: =D7/C7-1 -> 0.18214286 | G7: =D7/D5 -> 0.011029921
B8: აღმოსავლეთ აზია/წყნარი ოკეანის აუზი | C8: ='2026'!C114 -> 90672 | D8: ='2026'!D114 -> 70833 | E8: =D8-C8 -> -19839 | F8: =D8/C8-1 -> -0.21879963 | G8: =D8/D5 -> 0.0605223
B9: აფრიკა | C9: ='2026'!C174 -> 4428 | D9: ='2026'!D174 -> 3625 | E9: =D9-C9 -> -803 | F9: =D9/C9-1 -> -0.18134598 | G9: =D9/D5 -> 0.0030973323
B10: შუა აღმოსავლეთი | C10: ='2026'!C160 -> 26785 | D10: ='2026'!D160 -> 27779 | E10: =D10-C10 -> 994 | F10: =D10/C10-1 -> 0.037110323 | G10: =D10/D5 -> 0.023735391
B14: წყარო: საქართველოს შინაგან საქმეთა სამინისტრო, საინფორმაციო-ანალიტიკური დეპარტამენტი

Sheet ევროკავშირის ქვეყნები
B2: საერთაშორისო ვიზიტორების მიერ განხორციელებული ვიზიტები
B4: ევროკავშირის ქვეყნები და გაერთიანებული სამეფო | C4: 2025 I კვ | D4: 2026 I კვ | E4: ცვლილება 2025/2026 | F4: ცვლილება 2025/2026 %
B5: მთლიანი ჯამი | C5: =SUM(C6:C33) -> 73886 | D5: =SUM(D6:D33) -> 96226 | E5: =D5-C5 -> 22340 | F5: =D5/C5-1 -> 0.30235769
B6: ავსტრია | C6: 1478 | D6: 1537 | E6: =D6-C6 -> 59 | F6: =D6/C6-1 -> 0.039918809
B7: ბელგია | C7: 1371 | D7: 1632 | E7: =D7-C7 -> 261 | F7: =D7/C7-1 -> 0.19037199
B8: ბულგარეთი | C8: 1837 | D8: 2136 | E8: =D8-C8 -> 299 | F8: =D8/C8-1 -> 0.16276538
B9: გაერთიანებული სამეფო | C9: 6506 | D9: 9479 | E9: =D9-C9 -> 2973 | F9: =D9/C9-1 -> 0.4569628
B10: გერმანია | C10: 10212 | D10: 14051 | E10: =D10-C10 -> 3839 | F10: =D10/C10-1 -> 0.37593028
B11: დანია | C11: 863 | D11: 849 | E11: =D11-C11 -> -14 | F11: =D11/C11-1 -> -0.01622248
B12: ესპანეთი | C12: 2988 | D12: 4315 | E12: =D12-C12 -> 1327 | F12: =D12/C12-1 -> 0.44410977
B13: ესტონეთი | C13: 1332 | D13: 1138 | E13: =D13-C13 -> -194 | F13: =D13/C13-1 -> -0.14564565
B14: ირლანდია | C14: 1015 | D14: 1113 | E14: =D14-C14 -> 98 | F14: =D14/C14-1 -> 0.096551724
B15: იტალია | C15: 4170 | D15: 7117 | E15: =D15-C15 -> 2947 | F15: =D15/C15-1 -> 0.70671463
B16: კვიპროსი | C16: 1363 | D16: 1750 | E16: =D16-C16 -> 387 | F16: =D16/C16-1 -> 0.2839325
B17: ლატვია | C17: 3375 | D17: 2508 | E17: =D17-C17 -> -867 | F17: =D17/C17-1 -> -0.25688889
... B33: ხორვატია | C33: 297 | D33: 493 | E33: =D33-C33 -> 196 | F33: =D33/C33-1 -> 0.65993266
B37: წყარო: საქართველოს შინაგან საქმეთა სამინისტრო, საინფორმაციო-ანალიტიკური დეპარტამენტი

Sheet საზღვრის ტიპი
B2: საერთაშორისო ვიზიტორების მიერ განხორციელებული ვიზიტები
B4: ტიპი | C4: 2025 I კვ | D4: 2026 I კვ | E4: ცვლილება 2025/2026 | F4: ცვლილება 2025/2026 % | G4: წილი %
B5: სახმელეთო | C5: 659765 | D5: 621705 | E5: =D5-C5 -> -38060 | F5: =D5/C5-1 -> -0.057687207 | G5: =D5/'2026'!D4 -> 0.53120744
B6: საჰაერო | C6: 503009 | D6: 539159 | E6: =D6-C6 -> 36150 | F6: =D6/C6-1 -> 0.071867501 | G6: =D6/'2026'!D4 -> 0.46067712
B7: საზღვაო | C7: 7175 | D7: 7086 | E7: =D7-C7 -> -89 | F7: =D7/C7-1 -> -0.012404181 | G7: =D7/'2026'!D4 -> 0.006054537
B8: სარკინიგზო | C8: 2387 | D8: 2412 | E8: =D8-C8 -> 25 | F8: =D8/C8-1 -> 0.010473398 | G8: =D8/'2026'!D4 -> 0.0020609008
B12: წყარო: საქართველოს შინაგან საქმეთა სამინისტრო, საინფორმაციო-ანალიტიკური დეპარტამენტი

Sheet საზღვარი
B2: საერთაშორისო ვიზიტორების მიერ განხორციელებული ვიზიტები
B4: საზღვარი | C4: 2025 I კვ | D4: 2026 I კვ | E4: ცვლილება 2025/2026 | F4: ცვლილება 2025/2026 % | G4: წილი %
B5: თბილისის აეროპორტი | C5: 347977 | D5: 393560 | E5: =D5-C5 -> 45583 | F5: =D5/C5-1 -> 0.13099429 | G5: =D5/'2026'!D$4 -> 0.33627203
B6: სარფი | C6: 197239 | D6: 191832 | E6: =D6-C6 -> -5407 | F6: =D6/C6-1 -> -0.027413443 | G6: =D6/'2026'!D$4 -> 0.16390826
B7: ყაზბეგი | C7: 177522 | D7: 152550 | E7: =D7-C7 -> -24972 | F7: =D7/C7-1 -> -0.14066989 | G7: =D7/'2026'!D$4 -> 0.13034429
B8: სადახლო | C8: 142625 | D8: 136460 | E8: =D8-C8 -> -6165 | F8: =D8/C8-1 -> -0.043225241 | G8: =D8/'2026'!D$4 -> 0.1165964
B9: ქუთაისის აეროპორტი | C9: 89371 | D9: 97019 | E9: =D9-C9 -> 7648 | F9: =D9/C9-1 -> 0.085575858 | G9: =D9/'2026'!D$4 -> 0.082896574
B10: ბათუმის აეროპორტი | C10: 65661 | D10: 48580 | E10: =D10-C10 -> -17081 | F10: =D10/C10-1 -> -0.2601392 | G10: =D10/'2026'!D$4 -> 0.041508525
B11: ნინოწმინდა | C11: 47761 | D11: 46585 | E11: =D11-C11 -> -1176 | F11: =D11/C11-1 -> -0.0246226 | G11: =D11/'2026'!D$4 -> 0.039803924
B12: წითელი ხიდი | C12: 33314 | D12: 32936 | E12: =D12-C12 -> -378 | F12: =D12/C12-1 -> -0.011346581 | G12: =D12/'2026'!D$4 -> 0.02814172
B13: კარწახი | C13: 24590 | D13: 19928 | E13: =D13-C13 -> -4662 | F13: =D13/C13-1 -> -0.18958926 | G13: =D13/'2026'!D$4 -> 0.01702721
B14: ცოდნა | C14: 13364 | D14: 16768 | E14: =D14-C14 -> 3404 | F14: =D14/C14-1 -> 0.25471416 | G14: =D14/'2026'!D$4 -> 0.014327191
B15: გუგუთი | C15: 12199 | D15: 12572 | E15: =D15-C15 -> 373 | F15: =D15/C15-1 -> 0.030576277 | G15: =D15/'2026'!D$4 -> 0.010741976
B16: ვალე | C16: 11135 | D16: 12071 | E16: =D16-C16 -> 936 | F16: =D16/C16-1 -> 0.084059273 | G16: =D16/'2026'!D$4 -> 0.010313903
... B23: ახკერპი | C23: 16 | D23: 3 | E23: =D23-C23 -> -13 | F23: =D23/C23-1 -> -0.8125 | G23: =D23/'2026'!D$4 -> 2.5633095e-06
B24: ვახტანგისი | C24: 0 | D24: 0 | E24: =D24-C24 -> 0 | G24: =D24/'2026'!D$4 -> 0
B25: სამთაწყარო | C25: 0 | D25: 0 | E25: =D25-C25 -> 0 | G25: =D25/'2026'!D$4 -> 0
B29: წყარო: საქართველოს შინაგან საქმეთა სამინისტრო, საინფორმაციო-ანალიტიკური დეპარტამენტი

Sheet დემოგრაფია
B2: საერთაშორისო ვიზიტორების მიერ განხორციელებული ვიზიტები
B4: კატეგორია | D4: 2025 I კვ | E4: 2026 I კვ | F4: ცვლილება 2025/2026 | G4: ცვლილება 2025/2026 % | H4: წილი %
B5: ასაკი | C5: 15-30 | D5: 298788 | E5: 315129 | F5: =E5-D5 -> 16341 | G5: =E5/D5-1 -> 0.054690951 | H5: =E5/'2026'!D4 -> 0.26925772
C6: 31-50 | D6: 587958 | E6: 567308 | F6: =E6-D6 -> -20650 | G6: =E6/D6-1 -> -0.035121556 | H6: =E6/'2026'!D$4 -> 0.48472866
C7: 51-70 | D7: 266245 | E7: 269293 | F7: =E7-D7 -> 3048 | G7: =E7/D7-1 -> 0.011448102 | H7: =E7/'2026'!D$4 -> 0.23009377
C8: 71+ | D8: 19345 | E8: 18632 | F8: =E8-D8 -> -713 | G8: =E8/D8-1 -> -0.036857069 | H8: =E8/'2026'!D$4 -> 0.015919861
B9: სქესი | C9: კაცი | D9: 788598 | E9: 765351 | F9: =E9-D9 -> -23247 | G9: =E9/D9-1 -> -0.029478898 | H9: =E9/'2026'!D$4 -> 0.65394382
C10: ქალი | D10: 383738 | E10: 405011 | F10: =E10-D10 -> 21273 | G10: =E10/D10-1 -> 0.055436261 | H10: =E10/'2026'!D$4 -> 0.34605618
B14: წყარო: საქართველოს შინაგან საქმეთა სამინისტრო, საინფორმაციო-ანალიტიკური დეპარტამენტი

Sheet ტერმინები
B2: ტერმინი | C2: განსაზღვრება
B3: საერთაშორისო არარეზიდენტი მოგზაურების* ვიზიტები | C3: *მოგზაური არის ნებისმიერი ასაკის არარეზიდენტი პირი, რომელიც გადაადგილდება სხვადასხვა გეოგრაფიულ არეალს შორის ნებისმიერი ხანგრძლივობითა და მიზნით. ის გამორიცხავს საქართველოს რეზიდენტ სხვა ქვეყნის მოქალაქეებს და მოიცავს საქართველოს მოქალაქეებს, რომლებიც უცხო ქვეყნის რეზიდენტები არიან.
B4: საერთაშორისო ვიზიტორების* მიერ განხორციელებული ვიზიტები | C4: *ვიზიტორი არის 15 წლის ან უფროსი ასაკის საქართველოს არარეზიდენტი მოგზაური, რომელმაც განახორციელა ვიზიტი საკუთარი ჩვეული გარემოდან საქართველოს ტერიტორიაზე ერთ წელზე ნაკლები დროით. საქართველოში ჩვეული გარემოს განსასაზღვრად შემდეგი მეთოდი გამოიყენება, ჩვეულ გარემოში ითვლება ის ვიზიტები რომელიც თვეში 8-ჯერ ან 8-ზე მეტჯერ ხორციელდება.
B5: ტურისტული ვიზიტი* | C5: *ტურისტი არის ვიზიტორი, რომელმაც ღამე გაათენა საქართველოს ტერიტორიაზე.
B6: ერთდღიანი ვიზიტი* | C6: *ერთდღიანი ვიზიტორი (ექსკურსანტი) არის ვიზიტორი, რომელიც ღამეს არ ათენებს საქართველოს ტერიტორიაზე.
B7: სხვა (არატურისტული)* | C7: *სხვა კატეგორია- მოიცავს ყველა იმ ვიზიტს, რომელიც არ შედის საერთაშორისო ვიზიტორების მიერ განხორიცელებული ვიზიტების რაოდენობაში. ეს კატეგორია მოიცავს 14 წლის ან უმცროსი ასაკის მოგზაურების ვიზიტებს და ჩვეულ გარემოში განხორციელებულ ვიზიტებს (8 და 8-ზე მეტი თვეში).
